Workbook
Name _FAC1: [1]สรุป!$C$307

Sheet ปร.5
A1: สรุปผลการประมาณราคาค่าก่อสร้าง
A3: □ | B3: ประเภท | E3: บ้านพักอาศัย คสล. ชั้นเดียว
A4: □ | B4: เจ้าของอาคาร
A5: □ | B5: สถานที่ก่อสร้าง
A6: □ | B6: หน่วยงานออกแบบแปลนและรายการ
A7: □ | B7: แบบเลขที่ | Q7: รายการเลขที่
A8: □ | B8: ประมาณราคาตามแบบ | F8: ปร.4 | J8: จำนวน | L8: 5 | M8: แผ่น
A9: □ | B9: ประมาณราคาเมื่อวันที่ | F9: 44502
A11: ลำดับที่ | B11: รายการ | K11: ค่าวัสดุและค่าแรงงาน จำนวนเงิน / บาท | O11: ค่าดำเนินการ | R11: รวมค่าก่อสร้าง เป็นเงิน/บาท | U11: ส่วนต่าง
B12: บ้านพักอาศัย คสล. ชั้นเดียว | K12: =สรุปราคา!J27 -> 1744601.5 | O12: 1.15 | R12: =K12*O12 -> 2006291.7
A21: สรุป | B21: รวมค่าก่อสร้างเป็นเงินทั้งสิ้น | R21: =SUM(R12:T20) -> 2006291.7
B22: คิดเป็นเงินประมาณ (ตัวอักษร) | H22: ( | I22: =(BAHTTEXT((R22))) -> สองล้านบาทถ้วน | Q22: ) | R22: =+FLOOR(R21,10000) -> 2000000 | U22: **
A23: □ | B23: ขนาดหรือเนื้อที่อาคาร | G23: 70 | J23: ตารางเมตร
A24: □ | B24: เฉลี่ยราคาประมาณ | G24: =R22/G23 -> 28571.429 | J24: บาท / ตารางเมตร

Sheet สรุปราคา
A1: ประมาณราคาค่า ก่อสร้างบ้านพักอาศัย คสล. ชั้นเดียว | J1: แบบ ปร.4
A2: สถานที่ก่อสร้าง : | E2: แบบเลขที่ | J2: รายการเลขที่
A3: ประมาณราคาโดย | E3: ประมาณราคาเมื่อวันที่ | G3: =ปร.5!F9 -> 44502
A5: ลำดับที่ | B5: รายการ | C5: จำนวน | D5: จำนวน | E5: หน่วย | F5: ราคาวัสดุ | H5: ค่าแรงงาน | J5: รวมค่าวัสดุ และค่าแรงงาน | K5: หมายเหตุ | M5: 176
F6: ราคาหน่วยละ | G6: จำนวนเงิน | H6: ราคาหน่วยละ | I6: จำนวนเงิน
B7: สรุปราคาค่าวัสดุและแรงงาน
A8: 1 | B8: หมวดงานโครงสร้าง | J8: =Str!J52 -> 629671 | L8: =J8/J27 -> 0.3609254 | M8: =(J8*1.1)/70 -> 9894.83
A9: 2 | B9: หมวดงานสถาปัตยกรรม | J9: =arc!J96 -> 985285.5 | L9: =J9/J27 -> 0.5647625 | M9: =(J9*1.1)/70 -> 15483.058
A10: 3 | B10: หมวดงานระบบสุขาภิบาล | J10: =Sn!J55 -> 30295 | L10: =J10/J27 -> 0.017364997 | M10: =(J10*1.1)/70 -> 476.06429
A11: 4 | B11: หมวดงานระบบไฟฟ้า | C11: =+C8*2 -> 0 | J11: =EE!J66 -> 99350 | L11: =J11/J27 -> 0.056947102 | M11: =(J11*1.1)/70 -> 1561.2143
L14: =SUM(L8:L13) -> 1
O19: =Str!I52+arc!I96+Sn!J55+EE!J66 -> 628896 | P19: =(O19*1.15)/115 -> 6288.96
B27: รวมค่าวัสดุและแรงงาน | J27: =SUM(J8:J26) -> 1744601.5
C28: ชุด
C29: เหมารวม
C32: ชุด
C33: ชุด
C34: ชุด
C35: ชุด
C37: ชุด
C39: ชุด
C40: ชุด
C41: ชุด
C47: ม.
C48: ม.
... C112: เหมารวม

Sheet Str
A1: ประมาณราคาค่า ก่อสร้างบ้านพักอาศัย คสล. ชั้นเดียว | J1: แบบ ปร.4
A2: สถานที่ก่อสร้าง : | E2: แบบเลขที่ | J2: รายการเลขที่
A3: ประมาณราคาโดย | E3: ประมาณราคาเมื่อวันที่ | G3: =ปร.5!F9 -> 44502
D4: หมวดงานโครงสร้าง
A5: ลำดับที่ | B5: รายการ | C5: จำนวน | D5: จำนวน | E5: หน่วย | F5: ราคาวัสดุ | H5: ค่าแรงงาน | J5: รวมค่าวัสดุ และค่าแรงงาน | K5: หมายเหตุ
F6: ราคาหน่วยละ | G6: จำนวนเงิน | H6: ราคาหน่วยละ | I6: จำนวนเงิน
A7: 1 | B7: หมวดงานโครงสร้าง
A8: 1.1 | B8: งานปรับบริเวณและปักผัง
B9: ปรับบริเวณและปักผัง | D9: 148 | E9: ตร.ม. | F9: 100 | G9: =D9*F9 -> 14800 | H9: 80 | I9: =SUM(D9*H9) -> 11840 | J9: =I9+G9 -> 26640 | V9: (2.3),(3.1) | W9: 1800 | X9: ตร.ม. | Y9: 15 | Z9: =W9*Y9 -> 27000 | AA9: 15 | AB9: =SUM(W9*AA9) -> 27000 | AC9: =AB9+Z9 -> 54000 | AD9: =+J9-AC9 -> -27360
A10: 1.2 | B10: งานโครงสร้าง ค.ส.ล.
B11: ขุดดินฐานรากพร้อมถมกลับ | D11: 52 | E11: ลบ.ม. | F11: 0 | G11: 0 | H11: 350 | I11: =SUM(D11*H11) -> 18200 | J11: =I11+G11 -> 18200 | V11: (3.1) | W11: 78 | X11: ลบ.ม. | Y11: 0 | Z11: 0 | AA11: 99 | AB11: =SUM(W11*AA11) -> 7722 | AC11: =AB11+Z11 -> 7722 | AD11: =+J11-AC11 -> 10478
B12: ทรายหยาบ | D12: 5 | E12: ลบ.ม. | F12: 500 | G12: =D12*F12 -> 2500 | H12: 150 | I12: =SUM(D12*H12) -> 750 | J12: =I12+G12 -> 3250 | V12: (2.1),(3.1) | W12: 285 | X12: ลบ.ม. | Y12: 388.33 | Z12: =W12*Y12 -> 110674.05 | AA12: 91 | AB12: =SUM(W12*AA12) -> 25935 | AC12: =AB12+Z12 -> 136609.05 | AD12: =+J12-AC12 -> -133359.05
B13: คอนกรีตหยาบ | D13: 4 | E13: ลบ.ม. | F13: 2000 | G13: =D13*F13 -> 8000 | H13: 456 | I13: =SUM(D13*H13) -> 1824 | J13: =I13+G13 -> 9824 | V13: (2.1),(3.1) | W13: 15 | X13: ลบ.ม. | Y13: 1635.1 | Z13: =W13*Y13 -> 24526.5 | AA13: 398 | AB13: =SUM(W13*AA13) -> 5970 | AC13: =AB13+Z13 -> 30496.5 | AD13: =+J13-AC13 -> -20672.5
B14: งานคอนกรีต | AD14: =+J14-AC14 -> 0
B15: - ปูช้าง | D15: 50 | E15: ถุง | F15: 125 | G15: =D15*F15 -> 6250 | I15: =SUM(D15*H15) -> 0 | J15: =I15+G15 -> 6250 | AD15: =+J15-AC15 -> 6250
B16: - คอนกรีตโครงสร้าง ( 240 ksc. ทรงลูกบาศก์ ) | D16: 45 | E16: ลบ.ม. | F16: 2000 | G16: =D16*F16 -> 90000 | H16: 456 | I16: =SUM(D16*H16) -> 20520 | J16: =I16+G16 -> 110520 | L16: =D16*1.02 -> 45.9 | V16: (2.1),(3.1) | W16: =990+5 -> 995 | X16: ลบ.ม. | Y16: 1775.7 | Z16: =W16*Y16 -> 1766821.5 | AA16: 485 | AB16: =SUM(W16*AA16) -> 482575 | AC16: =AB16+Z16 -> 2249396.5 | AD16: =+J16-AC16 -> -2138876.5
B17: งานไม้แบบ | L17: =D17*1.02 -> #VALUE! | AD17: =+J17-AC17 -> 0
B18: - งานไม้แบบฐานราก | D18: 23 | E18: ฐาน | F18: 100 | G18: =D18*F18 -> 2300 | H18: 50 | I18: =SUM(D18*H18) -> 1150 | J18: =I18+G18 -> 3450 | L18: =D18*1.02 -> 23.46 | V18: (2.3),(3.1) | W18: =7950+40 -> 7990 | X18: ตร.ม. | Y18: 267 | Z18: =W18*Y18 -> 2133330 | AA18: 115 | AB18: =SUM(W18*AA18) -> 918850 | AC18: =AB18+Z18 -> 3052180 | AD18: =+J18-AC18 -> -3048730
B19: - งานไม้แบบเสาตอม่อ | D19: 23 | E19: ต้น | F19: 60 | G19: =D19*F19 -> 1380 | H19: 80 | I19: =SUM(D19*H19) -> 1840 | J19: =I19+G19 -> 3220 | L19: =D19*1.02 -> 23.46 | V19: (2.3),(3.1) | W19: =7950+40 -> 7990 | X19: ตร.ม. | Y19: 267 | Z19: =W19*Y19 -> 2133330 | AA19: 115 | AB19: =SUM(W19*AA19) -> 918850 | AC19: =AB19+Z19 -> 3052180 | AD19: =+J19-AC19 -> -3048960
B20: - งานไม้แบบเสา | D20: 23 | E20: ต้น | F20: 100 | G20: =D20*F20 -> 2300 | H20: 80 | I20: =SUM(D20*H20) -> 1840 | J20: =I20+G20 -> 4140 | L20: =D20*1.02 -> 23.46 | V20: (2.3),(3.1) | W20: =7950+40 -> 7990 | X20: ตร.ม. | Y20: 267 | Z20: =W20*Y20 -> 2133330 | AA20: 115 | AB20: =SUM(W20*AA20) -> 918850 | AC20: =AB20+Z20 -> 3052180 | AD20: =+J20-AC20 -> -3048040
B21: - งานไม้แบบท้องคาน | D21: 155 | E21: เมตร | F21: 50 | G21: =D21*F21 -> 7750 | H21: 40 | I21: =SUM(D21*H21) -> 6200 | J21: =I21+G21 -> 13950 | L21: =D21*1.02 -> 158.1 | V21: (2.3),(3.1) | W21: =7950+40 -> 7990 | X21: ตร.ม. | Y21: 267 | Z21: =W21*Y21 -> 2133330 | AA21: 115 | AB21: =SUM(W21*AA21) -> 918850 | AC21: =AB21+Z21 -> 3052180 | AD21: =+J21-AC21 -> -3038230
B22: - งานไม้แบบคาน | D22: 155 | E22: เมตร | F22: 60 | G22: =D22*F22 -> 9300 | H22: 35 | I22: =SUM(D22*H22) -> 5425 | J22: =I22+G22 -> 14725 | L22: =D22*1.02 -> 158.1 | V22: (2.3),(3.1) | W22: =7950+40 -> 7990 | X22: ตร.ม. | Y22: 267 | Z22: =W22*Y22 -> 2133330 | AA22: 115 | AB22: =SUM(W22*AA22) -> 918850 | AC22: =AB22+Z22 -> 3052180 | AD22: =+J22-AC22 -> -3037455
B23: - งานไม้แบบท้องพื้น | D23: 10 | E23: ตร.ม. | F23: 220 | G23: =D23*F23 -> 2200 | H23: 125 | I23: =SUM(D23*H23) -> 1250 | J23: =I23+G23 -> 3450 | L23: =D23*1.02 -> 10.2 | V23: (2.3),(3.1) | W23: =7950+40 -> 7990 | X23: ตร.ม. | Y23: 267 | Z23: =W23*Y23 -> 2133330 | AA23: 115 | AB23: =SUM(W23*AA23) -> 918850 | AC23: =AB23+Z23 -> 3052180 | AD23: =+J23-AC23 -> -3048730
B24: - งานไม้ค้ำยัน | D24: 1 | E24: งาน | F24: 12000 | G24: =D24*F24 -> 12000 | H24: 5000 | I24: =SUM(D24*H24) -> 5000 | J24: =I24+G24 -> 17000 | L24: =D24*1.02 -> 1.02 | V24: (2.3),(3.1) | W24: =7950+40 -> 7990 | X24: ตร.ม. | Y24: 267 | Z24: =W24*Y24 -> 2133330 | AA24: 115 | AB24: =SUM(W24*AA24) -> 918850 | AC24: =AB24+Z24 -> 3052180 | AD24: =+J24-AC24 -> -3035180
B25: - ตะปู | D25: 40 | E25: กก. | F25: 55 | G25: =D25*F25 -> 2200 | H25: 10 | I25: =SUM(D25*H25) -> 400 | J25: =I25+G25 -> 2600 | L25: =D25*1.02 -> 40.8 | V25: (2.1),(3.1) | W25: =+W20*0.25 -> 1997.5 | X25: กก. | Y25: 30.37 | Z25: =W25*Y25 -> 60664.075 | AA25: 0 | AB25: =SUM(W25*AA25) -> 0 | AC25: =AB25+Z25 -> 60664.075 | AD25: =+J25-AC25 -> -58064.075 | AE25: 155835 | AF25: 3484776.4 | AG25: =+AF25/AE25 -> 22.361963
B26: งานเหล็กเสริมคอนกรีต | I26: 0 | Z26: 0 | AB26: 0 | AC26: 0 | AD26: =+J26-AC26 -> 0 | AE26: 130036 | AF26: 3353982.3 | AG26: =+AF26/AE26 -> 25.792721
B27: - เหล็กเส้นกลม SR-24 | AD27: =+J27-AC27 -> 0
B28: - RB 6 mm. | D28: 14 | E28: เส้น | F28: 80 | G28: =D28*F28 -> 1120 | H28: 20 | I28: =SUM(D28*H28) -> 280 | J28: =I28+G28 -> 1400 | L28: =D28*1.02 -> 14.28 | V28: (2.1),(3.1) | W28: =525+2400+40+700 -> 3665 | X28: กก. | Y28: 17.9 | Z28: =W28*Y28 -> 65603.5 | AA28: 4.1 | AB28: =SUM(W28*AA28) -> 15026.5 | AC28: =AB28+Z28 -> 80630 | AD28: =+J28-AC28 -> -79230
B29: - RB 9 mm. | D29: 78 | E29: เส้น | F29: 180 | G29: =D29*F29 -> 14040 | H29: 49 | I29: =SUM(D29*H29) -> 3822 | J29: =I29+G29 -> 17862 | L29: =D29*1.02 -> 79.56 | V29: (2.1),(3.1) | W29: =37810+760+8500+500+100+2500 -> 50170 | X29: กก. | Y29: 16.76 | Z29: =W29*Y29 -> 840849.2 | AA29: 4.1 | AB29: =SUM(W29*AA29) -> 205697 | AC29: =AB29+Z29 -> 1046546.2 | AD29: =+J29-AC29 -> -1028684.2
B30: - เหล็กข้ออ้อย SD-40 | L30: =D30*1.02 -> 0 | AD30: =+J30-AC30 -> 0
B31: - DB 12 mm. | D31: 247 | E31: เส้น | F31: 270 | G31: =D31*F31 -> 66690 | H31: 150 | I31: =SUM(D31*H31) -> 37050 | J31: =I31+G31 -> 103740 | L31: =D31/78*70 -> 221.66667 | V31: (2.1),(3.1) | W31: =45400+400+210+200 -> 46210 | X31: กก. | Y31: 14.88 | Z31: =W31*Y31 -> 687604.8 | AA31: 3.3 | AB31: =SUM(W31*AA31) -> 152493 | AC31: =AB31+Z31 -> 840097.8 | AD31: =+J31-AC31 -> -736357.8
B32: - ลวดผูกเหล็ก | D32: 50 | E32: ขด | F32: 100 | G32: =D32*F32 -> 5000 | I32: =SUM(D32*H32) -> 0 | J32: =I32+G32 -> 5000 | V32: (2.1) | W32: =ROUND(+(W28+W29+W31+#REF!+#REF!)/1000*30,0) -> #REF! | X32: กก. | Y32: 35.05 | Z32: =W32*Y32 -> #REF! | AA32: 0 | AB32: =SUM(W32*AA32) -> #REF! | AC32: =AB32+Z32 -> #REF! | AD32: =+J32-AC32 -> #REF!
B33: งานพื้นสำเร็จรูปแบบ | AD33: =+J33-AC33 -> 0
B34: - แผ่นพื้นสำเร็จรูป รับ นน.ปลอดภัย 200 กก./ ตร.ม. | D34: 138 | E34: ตร.ม. | F34: 300 | G34: =D34*F34 -> 41400 | H34: 250 | I34: =SUM(D34*H34) -> 34500 | J34: =I34+G34 -> 75900 | V34: (2.2),(3.1) | W34: 3200 | X34: ตร.ม. | Y34: 204 | Z34: =W34*Y34 -> 652800 | AA34: 25 | AB34: =SUM(W34*AA34) -> 80000 | AC34: =AB34+Z34 -> 732800 | AD34: =+J34-AC34 -> -656900
B35: - Wire mesh 4มม. @ 0.20 ม. | D35: 2 | E35: ม้วน | F35: 3700 | G35: =D35*F35 -> 7400 | H35: 750 | I35: =SUM(D35*H35) -> 1500 | J35: =I35+G35 -> 8900 | L35: =(G34+#REF!+G35)/220 -> #REF! | V35: (2.1),(3.1) | W35: 3200 | X35: ตร.ม. | Y35: 30 | Z35: =W35*Y35 -> 96000 | AA35: 5 | AB35: =SUM(W35*AA35) -> 16000 | AC35: =AB35+Z35 -> 112000 | AD35: =+J35-AC35 -> -103100
B36: รวมราคางานโครงสร้าง ค.ส.ล. | G36: =SUM(G9:G35) -> 296630 | I36: =SUM(I9:I35) -> 153391 | J36: =SUM(J9:J35) -> 450021 | Z36: =SUM(Z9:Z35) -> #REF! | AB36: =SUM(AB9:AB35) -> #REF! | AC36: =SUM(AC8:AC35) -> #REF! | AD36: =+J36-AC36 -> #REF!
A37: 1.3 | B37: งานโครงหลังคา
B38: งานโครงเหล็กรูปพรรณ | G38: =D38*F38 -> 0 | I38: =SUM(D38*H38) -> 0 | J38: =I38+G38 -> 0
B39: - เหล็กกล่อง 100 x 50 x2.0 mm. | M39: 450 | N39: 14393.75 | O39: 24.39
B40: - เหล็ก C - 100 x 50 x 20 x 2.0 mm. | D40: 93 | E40: ท่อน | F40: 800 | G40: =D40*F40 -> 74400 | H40: 150 | I40: =SUM(D40*H40) -> 13950 | J40: =I40+G40 -> 88350 | M40: 450 | N40: 14393.75 | O40: 24.39
...

Sheet arc
A1: ประมาณราคาค่า ก่อสร้างบ้านพักอาศัย คสล. ชั้นเดียว | J1: แบบ ปร.4
A2: สถานที่ก่อสร้าง : | E2: แบบเลขที่ | J2: รายการเลขที่
A3: ประมาณราคาโดย | E3: ประมาณราคาเมื่อวันที่ | G3: =ปร.5!F9 -> 44502
D4: หมวดงานสถาปัตยกรรม
A5: ลำดับที่ | B5: รายการ | C5: จำนวน | D5: จำนวน | E5: หน่วย | F5: ราคาวัสดุ | H5: ค่าแรงงาน | J5: รวมค่าวัสดุ และค่าแรงงาน | K5: หมายเหตุ
F6: ราคาหน่วยละ | G6: จำนวนเงิน | H6: ราคาหน่วยละ | I6: จำนวนเงิน
A7: 2 | B7: หมวดงานสถาปัตยกรรม
A8: 2.1 | B8: งานผนัง | G8: =D8*F8 -> 0 | I8: =SUM(D8*H8) -> 0 | J8: =I8+G8 -> 0
B9: - งานก่ออิฐบล็อกตัน ครึ่งแผ่น | D9: 380 | E9: ตร.ม. | G9: =D9*F9 -> 0 | H9: 100 | I9: =SUM(D9*H9) -> 38000 | J9: =I9+G9 -> 38000
B10: - อิฐมอญ | D10: 15315 | E10: ก้อน | F10: 2.5 | G10: =D10*F10 -> 38287.5 | I10: =SUM(D10*H10) -> 0 | J10: =I10+G10 -> 38287.5
B11: - ปูนก่อเสือ | D11: 120 | E11: ถุง | F11: 120 | G11: =D11*F11 -> 14400 | I11: =SUM(D11*H11) -> 0 | J11: =I11+G11 -> 14400
B12: - ทราย | D12: 12 | E12: ลบ.ม. | F12: 400 | G12: =D12*F12 -> 4800 | H12: 50 | I12: =SUM(D12*H12) -> 600 | J12: =I12+G12 -> 5400
B13: - งานฉาบ | C13: =+#REF! -> #REF! | D13: 760 | E13: ตร.ม. | G13: =D13*F13 -> 0 | H13: 100 | I13: =SUM(D13*H13) -> 76000 | J13: =I13+G13 -> 76000
B14: - ปูนฉาบเสือพลัส | D14: 120 | E14: ถุง | F14: 120 | G14: =D14*F14 -> 14400 | I14: =SUM(D14*H14) -> 0 | J14: =I14+G14 -> 14400
B15: - ทรายฉาบ | D15: 15 | E15: ลบ.ม. | F15: 700 | G15: =D15*F15 -> 10500 | H15: 50 | I15: =SUM(D15*H15) -> 750 | J15: =I15+G15 -> 11250
B16: - งานสกิมภายใน | C16: =+#REF! -> #REF! | D16: 325 | E16: ตร.ม. | F16: 50 | G16: =D16*F16 -> 16250 | H16: 50 | I16: =SUM(D16*H16) -> 16250 | J16: =I16+G16 -> 32500
B17: - งานสกิมภายนอก | C17: =+#REF! -> #REF! | D17: 155 | E17: ตร.ม. | F17: 50 | G17: =D17*F17 -> 7750 | H17: 60 | I17: =SUM(D17*H17) -> 9300 | J17: =I17+G17 -> 17050
B18: - งานกรุกระเบื้องผนังห้องน้ำ (รวมปูนฉาบรองพื้น) | D18: 52 | E18: ตร.ม. | F18: 500 | G18: =D18*F18 -> 26000 | H18: 150 | I18: =SUM(D18*H18) -> 7800 | J18: =I18+G18 -> 33800
B19: - งานกรุกระเบื้องผนังห้องครัว (รวมปูนฉาบรองพื้น) | D19: 8 | E19: ตร.ม. | F19: 500 | G19: =D19*F19 -> 4000 | H19: 150 | I19: =SUM(D19*H19) -> 1200 | J19: =I19+G19 -> 5200
B20: - งานผนัง กรุไม้เทียมสำเร็จรูป ยึดติดผนัง | D20: 2.5 | E20: ตร.ม. | F20: 250 | G20: =D20*F20 -> 625 | H20: 150 | I20: =SUM(D20*H20) -> 375 | J20: =I20+G20 -> 1000
B21: - งานผนัง กรุหิบทรายตกแต่ง | D21: 10 | E21: ตร.ม. | F21: 350 | G21: =D21*F21 -> 3500 | H21: 330 | I21: =SUM(D21*H21) -> 3300 | J21: =I21+G21 -> 6800
B22: - บัวปูนปั้นสำเร็จรูป | D22: 163 | E22: เมตร | F22: 60 | G22: =D22*F22 -> 9780 | H22: 30 | I22: =SUM(D22*H22) -> 4890 | J22: =I22+G22 -> 14670
I24: =SUM(D24*H24) -> 0 | J24: =I24+G24 -> 0
B25: รวมราคาลำดับที่ 2.1 | G25: =SUM(G8:G24) -> 150292.5 | I25: =SUM(I8:I24) -> 158465 | J25: =SUM(J8:J24) -> 308757.5
A26: 2.2 | B26: งานพื้น | I26: =SUM(D26*H26) -> 0 | J26: =I26+G26 -> 0
B27: - F1 พื้นปูกระเบื้อง ขนาด 60x60 ซม. | C27: ตร.ม. | D27: 128 | E27: ตร.ม. | F27: 560 | G27: =D27*F27 -> 71680 | H27: 150 | I27: =SUM(D27*H27) -> 19200 | J27: =I27+G27 -> 90880
B28: - F2 พื้นปูกระเบื้องห้องน้ำ (กันลื่น) | C28: ตร.ม. | D28: 10 | E28: ตร.ม. | F28: 560 | G28: =D28*F28 -> 5600 | H28: 150 | I28: =SUM(D28*H28) -> 1500 | J28: =I28+G28 -> 7100
B29: - F3 พื้นปูกระเบื้องระเบียง (กันลื่น) | C29: ตร.ม. | D29: 25 | E29: ตร.ม. | F29: 560 | G29: =D29*F29 -> 14000 | H29: 220 | I29: =SUM(D29*H29) -> 5500 | J29: =I29+G29 -> 19500
B30: - บัวเชิงผนัง PVC ลายไม้ | C30: ตร.ม. | D30: 124 | E30: ม. | F30: 90 | G30: =D30*F30 -> 11160 | H30: 60 | I30: =SUM(D30*H30) -> 7440 | J30: =I30+G30 -> 18600
B32: รวมราคาลำดับที่ 2.2 | G32: =SUM(G26:G31) -> 102440 | I32: =SUM(I26:I31) -> 33640 | J32: =SUM(J26:J31) -> 136080
A33: 2.3 | B33: งานผ้าเพดาน | G33: =D33*F33 -> 0 | I33: =SUM(D33*H33) -> 0 | J33: =I33+G33 -> 0
B34: - ฝ้าเพดานยิบซั่มบอร์ดหนา 9 มม. | D34: 128 | E34: ตร.ม. | F34: 250 | G34: =D34*F34 -> 32000 | H34: 100 | I34: =SUM(D34*H34) -> 12800 | J34: =I34+G34 -> 44800
B35: โครงเคร่า C-line 1 ด้าน ฉาบเรียบ ทาสี | G35: =D35*F35 -> 0 | I35: =SUM(D35*H35) -> 0 | J35: =I35+G35 -> 0
B36: - งานฝ้าเพดานยิปซั่มบอร์ดกันชื้น หนา 9 มม. | D36: 10 | E36: ตร.ม. | F36: 200 | G36: =D36*F36 -> 2000 | H36: 100 | I36: =SUM(D36*H36) -> 1000 | J36: =I36+G36 -> 3000
B37: โครงเคร่า C-line 1 ด้าน ฉาบเรียบ ทาสี
B38: - ฝ้าเพดานสมาร์ทบอร์ด 6 มม. +เพดานสมาร์ทบอร์ดระบายอากาศ46 มม. | D38: 40 | E38: ตร.ม. | F38: 220 | G38: =D38*F38 -> 8800 | H38: 85 | I38: =SUM(D38*H38) -> 3400 | J38: =I38+G38 -> 12200
B39: โครงเคร่า C-line 1 ด้าน ภายในกรุตาข่ายกันแมลง
B41: รวมราคาลำดับที่ 2.3 | G41: =SUM(G33:G39) -> 42800 | I41: =SUM(I33:I39) -> 17200 | J41: =SUM(J33:J39) -> 60000
A42: 2.4 | B42: งานหลังคา | G42: =D42*F42 -> 0 | I42: =SUM(D42*H42) -> 0 | J42: =I42+G42 -> 0
B43: หลังคามุงกระเบื้องแผ่นเรียบตราเพรช | D43: 2850 | E43: แผ่น | F43: 25 | G43: =D43*F43 -> 71250 | H43: 5 | I43: =D43*H43 -> 14250 | J43: =I43+G43 -> 85500
...

Sheet Sn
A1: ประมาณราคาค่า ก่อสร้างบ้านพักอาศัย คสล. ชั้นเดียว
A2: สถานที่ก่อสร้าง : | E2: แบบเลขที่
A3: ประมาณราคาโดย | E3: ประมาณราคาเมื่อวันที่ | G3: =ปร.5!F9 -> 44502
D4: หมวดงานระบบสุขาภิบาล
A5: ลำดับที่ | B5: รายการ | C5: จำนวน | D5: จำนวน | E5: หน่วย | F5: ราคาวัสดุ | H5: ค่าแรงงาน | J5: รวมค่าวัสดุ และค่าแรงงาน | K5: หมายเหตุ
F6: ราคาหน่วยละ | G6: จำนวนเงิน | H6: ราคาหน่วยละ | I6: จำนวนเงิน
A7: 3 | B7: หมวดงานระบบสุขาภิบาล
A8: 3.1 | B8: งานระบบน้ำประปา | N8: 4205 | O8: 4055
B9: GATE VALVE | J9: =I9+G9 -> 0
B10: DIA. 1" | D10: 0 | E10: EA | F10: 150 | G10: =D10*F10 -> 0 | H10: 50 | I10: =SUM(D10*H10) -> 0 | J10: =I10+G10 -> 0 | M10: - ถังบำบัดสำเร็จรูป 1000 ลิตร | N10: ชุด | O10: 1 | P10: 5000 | Q10: =O10*P10 -> 5000 | R10: 500
B11: DIA. 3/4" | D11: 3 | E11: EA | F11: 100 | G11: =D11*F11 -> 300 | I11: =SUM(D11*H11) -> 0 | J11: =I11+G11 -> 300 | M11: - บ่อซึม | N11: ชุด | O11: 1 | P11: 1000 | Q11: =O11*P11 -> 1000 | R11: 500
B12: ท่อ PVC class 13.5 | G12: =D12*F12 -> 0 | I12: =SUM(D12*H12) -> 0 | J12: =I12+G12 -> 0 | M12: - ฐาน ค.ส.ล. รับถังบำบัด และทรายถม | N12: ชุด | O12: 1 | P12: 500 | Q12: =O12*P12 -> 500 | R12: 500
B13: DIA. 1" | D13: 6 | E13: ท่อน | F13: 90 | G13: =D13*F13 -> 540 | H13: 30 | I13: =SUM(D13*H13) -> 180 | J13: =I13+G13 -> 720 | M13: - ท่อประปา PVC. Ø 1 นิ้ว class 13.5 | N13: เมตร | O13: 32 | P13: 20 | Q13: =O13*P13 -> 640 | R13: 30
B14: DIA. 3/4" | D14: 3 | E14: ท่อน | F14: 140 | G14: =D14*F14 -> 420 | H14: 45 | I14: =SUM(D14*H14) -> 135 | J14: =I14+G14 -> 555 | M14: - ท่อประปา PVC. Ø 3/4 นิ้ว class 13.5 | N14: เมตร | O14: 16 | P14: 14 | Q14: =O14*P14 -> 224 | R14: 30
B15: DIA. 1/2" | D15: 2 | E15: ท่อน | F15: 70 | G15: =D15*F15 -> 140 | H15: 25 | I15: =SUM(D15*H15) -> 50 | J15: =I15+G15 -> 190 | M15: - ท่อประปา PVC. Ø 1/2 นิ้ว class 13.5 | N15: เมตร | O15: 24 | P15: 10 | Q15: =O15*P15 -> 240 | R15: 30
B16: อุปกรณ์ข้อต่อ | D16: 1 | E16: LOT | F16: 3000 | G16: =D16*F16 -> 3000 | I16: =SUM(D16*H16) -> 0 | J16: =I16+G16 -> 3000 | M16: - ก็อกน้ำสนาม Ø 3/4 นิ้ว | N16: ตัว | O16: 2 | P16: 150 | Q16: =O16*P16 -> 300 | R16: 80
M17: - วาล์ว Ø 3/4 นิ้ว | N17: ตัว | O17: 2 | P17: 100 | Q17: =O17*P17 -> 200 | R17: 50
B18: รวมงานงานระบบน้ำประปา | G18: =SUM(G9:G17) -> 4400 | I18: =SUM(I9:I17) -> 365 | J18: =SUM(J9:J17) -> 4765 | M18: - วาล์ว Ø 1 นิ้ว | N18: ตัว | O18: 1 | P18: 150 | Q18: =O18*P18 -> 150 | R18: 50
A19: 3.2 | B19: ระบบท่อน้ำโสโครก, ท่อน้ำทิ้ง (S,W,KW) | G19: =D19*F19 -> 0 | I19: =SUM(D19*H19) -> 0 | J19: =I19+G19 -> 0 | M19: - ท่อระบายน้ำ PVC. Ø 3 นิ้ว class 8.5 | N19: เมตร | O19: 4 | P19: 80 | Q19: =O19*P19 -> 320 | R19: 75
B20: ท่อ PVC class 8.5 | G20: =D20*F20 -> 0 | I20: =SUM(D20*H20) -> 0 | J20: =I20+G20 -> 0 | M20: - ท่อระบายน้ำ PVC. Ø 4 นิ้ว class 8.5 | N20: เมตร | O20: 20 | P20: 120 | Q20: =O20*P20 -> 2400 | R20: 50
B21: DIA. 4" | D21: 4 | E21: ท่อน | F21: 820 | G21: =D21*F21 -> 3280 | H21: 100 | I21: =SUM(D21*H21) -> 400 | J21: =I21+G21 -> 3680 | M21: - ท่อใยหิน Ø 8 นิ้ว | N21: เมตร | O21: 16 | P21: 75 | Q21: =O21*P21 -> 1200 | R21: 50
B22: DIA. 3" | D22: 0 | E22: M | G22: =D22*F22 -> 0 | I22: =SUM(D22*H22) -> 0 | J22: =I22+G22 -> 0 | M22: - ถังดักไขมัน 30 ลิตร | N22: ชุด | O22: 1 | P22: 1000 | Q22: =O22*P22 -> 1000 | R22: 150
B23: DIA. 2" | D23: 4 | E23: ท่อน | F23: 250 | G23: =D23*F23 -> 1000 | H23: 50 | I23: =SUM(D23*H23) -> 200 | J23: =I23+G23 -> 1200 | M23: - บ่อพัก | N23: ชุด | O23: 2 | P23: 500 | Q23: =O23*P23 -> 1000 | R23: 100
B24: อุปกรณ์ข้อต่อ | D24: 1 | E24: LOT | F24: 3000 | G24: =D24*F24 -> 3000 | I24: =SUM(D24*H24) -> 0 | J24: =I24+G24 -> 3000 | M24: - บ่อดักขยะ | N24: ชุด | O24: 1 | P24: 1000 | Q24: =O24*P24 -> 1000 | R24: 200
B25: ถังบำบัดสำเร็จรูป ขนาด 1000 ลิตร | D25: 1 | E25: SET | F25: 4000 | G25: =D25*F25 -> 4000 | H25: 1500 | I25: =SUM(D25*H25) -> 1500 | J25: =I25+G25 -> 5500
B26: วัสดุอุปกรณ์ประกอบบ่อพักน้ำเสีย | D26: 5 | E26: SET | F26: 850 | G26: =D26*F26 -> 4250 | H26: 300 | I26: =SUM(D26*H26) -> 1500 | J26: =I26+G26 -> 5750
B27: บ่อซึม | D27: 2 | E27: SET | F27: 1500 | G27: =D27*F27 -> 3000 | H27: 500 | I27: =SUM(D27*H27) -> 1000 | J27: =I27+G27 -> 4000
B29: รวมราคางานระบบท่อน้ำโสโครก, ท่อน้ำทิ้ง | C29: 158.38 | G29: =SUM(G21:G27) -> 18530 | I29: =SUM(I21:I27) -> 4600 | J29: =SUM(J21:J27) -> 23130
A30: 3.3 | B30: ระบบท่ออากาศ (V) | C30: 126.28
B31: ท่อ PVC class 5.0 | C31: 246.66 | G31: =D31*F31 -> 0 | I31: =SUM(D31*H31) -> 0 | J31: =I31+G31 -> 0
B32: DIA. 2" | D32: 1 | E32: ท่อ | F32: 200 | G32: =D32*F32 -> 200 | H32: 50 | I32: =SUM(D32*H32) -> 50 | J32: =I32+G32 -> 250
B33: DIA. 1 1/2" | D33: 0 | E33: M | G33: =D33*F33 -> 0 | I33: =SUM(D33*H33) -> 0 | J33: =I33+G33 -> 0
B34: อุปกรณ์ข้อต่อ | D34: 1 | E34: LOT | F34: 2000 | G34: =D34*F34 -> 2000 | H34: 150 | I34: =SUM(D34*H34) -> 150 | J34: =I34+G34 -> 2150
B35: SUPPORT AND HANGER | E35: LOT | G35: =D35*F35 -> 0 | I35: =SUM(D35*H35) -> 0 | J35: =I35+G35 -> 0
B36: PAINTING AND TESTING | C36: =2886.98+760.6 -> 3647.58 | E36: LOT | G36: =D36*F36 -> 0 | I36: =SUM(D36*H36) -> 0 | J36: =I36+G36 -> 0
B38: รวมราคาระบบท่ออากาศ | G38: =SUM(G31:G36) -> 2200 | I38: =SUM(I31:I36) -> 200 | J38: =SUM(J31:J36) -> 2400
A39: 3.4 | B39: ระบบระบายน้ำฝน | C39: =#REF!*2 -> #REF!
A40: 3.4.1 | B40: ท่อ PVC class 8.5
B41: DIA. 4" | D41: 0 | E41: M | G41: =D41*F41 -> 0 | I41: =SUM(D41*H41) -> 0 | J41: =I41+G41 -> 0
B42: อุปกรณ์ข้อต่อ | D42: 0 | E42: LOT | G42: =D42*F42 -> 0 | I42: =SUM(D42*H42) -> 0 | J42: =I42+G42 -> 0
...

Sheet EE
A1: ประมาณราคาค่า ก่อสร้างบ้านพักอาศัย คสล. ชั้นเดียว
A2: สถานที่ก่อสร้าง : | E2: แบบเลขที่
A3: ประมาณราคาโดย | E3: ประมาณราคาเมื่อวันที่ | G3: =ปร.5!F9 -> 44502
D4: หมวดงานระบบไฟฟ้าและสื่อสาร
A5: ลำดับที่ | B5: รายการ | C5: จำนวน | D5: จำนวน | E5: หน่วย | F5: ราคาวัสดุ | H5: ค่าแรงงาน | J5: รวมค่าวัสดุ และค่าแรงงาน | K5: หมายเหตุ
F6: ราคาหน่วยละ | G6: จำนวนเงิน | H6: ราคาหน่วยละ | I6: จำนวนเงิน
A7: 4 | B7: หมวดงานระบบไฟฟ้า
A8: 4.1 | B8: PANEL BOARD
B9: CONSUMER UNIT 12 Ch | D9: 1 | E9: SET | F9: 8500 | G9: =SUM(D9*F9) -> 8500 | I9: =SUM(D9*H9) -> 0 | J9: =SUM(G9+I9) -> 8500
B10: ACCESSORIES | D10: 1 | E10: LOT | F10: 3000 | G10: =SUM(D10*F10) -> 3000 | I10: =SUM(D10*H10) -> 0 | J10: =SUM(G10+I10) -> 3000
B12: รวมราคา PANEL BOARD | G12: =SUM(G9:G10) -> 11500 | I12: =SUM(I9:I10) -> 0 | J12: =SUM(J9:J10) -> 11500
A13: 4.2 | B13: LIGHTING FIXTURE
B14: โคมไฟระย้า | D14: 0 | E14: SET | G14: =SUM(D14*F14) -> 0 | I14: =SUM(D14*H14) -> 0 | J14: =SUM(G14+I14) -> 0 | M14: - LOAD CENTER - เมน 63 Amp 1 Phase | N14: ชุด | O14: 1 | P14: 350 | Q14: =O14*P14 -> 350 | R14: 500
B15: โคมไฟ LED PANEL BOARD 24 W. | D15: 10 | E15: SET | F15: 750 | G15: =SUM(D15*F15) -> 7500 | H15: 350 | I15: =SUM(D15*H15) -> 3500 | J15: =SUM(G15+I15) -> 11000 | M15: - โคมไฟระย้า | N15: ชุด | O15: 1 | P15: 3500 | Q15: =O15*P15 -> 3500 | R15: 400
B16: โคมไฟ DOWN LIGHT LED PANEL BOARD 12 W. | D16: 11 | E16: SET | F16: 500 | G16: =SUM(D16*F16) -> 5500 | H16: 350 | I16: =SUM(D16*H16) -> 3850 | J16: =SUM(G16+I16) -> 9350 | M16: - โคมไฟครอบแก้ว 32w. | N16: ชุด | O16: 5 | P16: 500 | Q16: =O16*P16 -> 2500 | R16: 100
B17: โคมไฟติดผนัง | D17: 4 | E17: SET | F17: 1000 | G17: =SUM(D17*F17) -> 4000 | H17: 350 | I17: =SUM(D17*H17) -> 1400 | J17: =SUM(G17+I17) -> 5400 | M17: - โคมไฟดาวน์ไลท์ขอบสีขาว 18 w. | N17: ชุด | O17: 29 | P17: 200 | Q17: =O17*P17 -> 5800 | R17: 100
B18: พัดลมระบายอากาศ | D18: 0 | E18: SET | G18: =SUM(D18*F18) -> 0 | I18: =SUM(D18*H18) -> 0 | J18: =SUM(G18+I18) -> 0 | M18: - โคมไฟติดผนัง | N18: ชุด | O18: 4 | P18: 500 | Q18: =O18*P18 -> 2000 | R18: 100
B19: Fu 1*18 W | D19: 1 | E19: SET | F19: 350 | G19: =SUM(D19*F19) -> 350 | H19: 350 | I19: =SUM(D19*H19) -> 350 | J19: =SUM(G19+I19) -> 700 | M19: - สวิทซ์ ปิด-เปิดทางเดียวชนิดฝังในผนัง | N19: ชุด | O19: 9 | P19: 150 | Q19: =O19*P19 -> 1350 | R19: 100
M21: - ท่อร้อยสายไฟ PVC. 3/8" | N21: ท่อน | O21: 50 | P21: 40 | Q21: =O21*P21 -> 2000 | R21: 10
B22: รวมราคา LIGHTING FIXTURE | G22: =SUM(G14:G19) -> 17350 | I22: =SUM(I14:I19) -> 9100 | J22: =SUM(J14:J19) -> 26450 | M22: - ท่อร้อยสายไฟ PVC. 1/2" | N22: ท่อน | O22: 30 | P22: 50 | Q22: =O22*P22 -> 1500 | R22: 10
A23: 4.3 | B23: CABLE AND WIRE | M23: - ท่ออ่อน | N23: ม้วน | O23: 1 | P23: 550 | Q23: =O23*P23 -> 550 | R23: 0
B24: IEC 01. # 25 SQ.MM | D24: 0 | E24: M | G24: =SUM(D24*F24) -> 0 | I24: =SUM(D24*H24) -> 0 | J24: =SUM(G24+I24) -> 0 | M24: - สายดินพร้อมอุปกรณ์ | N24: งาน | O24: 1 | P24: 1000 | Q24: =O24*P24 -> 1000 | R24: 0
B25: IEC 01. # 10 SQ.MM | D25: 0 | E25: M | G25: =SUM(D25*F25) -> 0 | I25: =SUM(D25*H25) -> 0 | J25: =SUM(G25+I25) -> 0
B26: IEC 01. # 4 SQ.MM | D26: 300 | E26: M | F26: 20 | G26: =SUM(D26*F26) -> 6000 | H26: 20 | I26: =SUM(D26*H26) -> 6000 | J26: =SUM(G26+I26) -> 12000
B27: IEC 01. # 2.5 SQ.MM | D27: 600 | E27: M | F27: 17 | G27: =SUM(D27*F27) -> 10200 | H27: 15 | I27: =SUM(D27*H27) -> 9000 | J27: =SUM(G27+I27) -> 19200
B28: ท่อร้อยสาย | D28: 300 | E28: M | F28: 18 | G28: =SUM(D28*F28) -> 5400 | H28: 15 | I28: =SUM(D28*H28) -> 4500 | J28: =SUM(G28+I28) -> 9900
B29: เมนเครื่องทำน้ำร้อน | D29: 2 | E29: SET | F29: 600 | G29: =SUM(D29*F29) -> 1200 | H29: 250 | I29: =SUM(D29*H29) -> 500 | J29: =SUM(G29+I29) -> 1700
B30: ACCESSORIES | D30: 1 | E30: LOT | F30: 3000 | G30: =SUM(D30*F30) -> 3000 | I30: =SUM(D30*H30) -> 0 | J30: =SUM(G30+I30) -> 3000 | M30: - B29 | N30: จุด | O30: 4 | P30: 500 | Q30: =O30*P30 -> 2000 | R30: 120 | S30: =+O30*R30 -> 480
M31: - เมนเครื่องทำน้ำอุ่น | N31: จุด | O31: 1 | P31: 500 | Q31: =O31*P31 -> 500 | R31: 120 | S31: =+O31*R31 -> 120
B32: รวมราคา CABLE AND WIRE | G32: =SUM(G24:G31) -> 25800 | I32: =SUM(I24:I31) -> 20000 | J32: =SUM(J24:J31) -> 45800
A33: 4.4 | B33: SWITCH, RECEPTACLE AND OTHER EQUIPMENT
B34: สวิทซ์ไฟฟ้า | D34: 19 | E34: SET | F34: 200 | G34: =SUM(D34*F34) -> 3800 | H34: 150 | I34: =SUM(D34*H34) -> 2850 | J34: =SUM(G34+I34) -> 6650
B35: สวิทซ์ไฟฟ้า 2 ทาง | D35: 0 | E35: SET | G35: =SUM(D35*F35) -> 0 | H35: 115 | I35: =SUM(D35*H35) -> 0 | J35: =SUM(G35+I35) -> 0
B36: เต้ารับไฟฟ้า | D36: 17 | E36: SET | F36: 200 | G36: =SUM(D36*F36) -> 3400 | H36: 150 | I36: =SUM(D36*H36) -> 2550 | J36: =SUM(G36+I36) -> 5950
B37: ACCESSORIES | D37: 1 | E37: LOT | F37: 3000 | G37: =SUM(D37*F37) -> 3000 | I37: =SUM(D37*H37) -> 0 | J37: =SUM(G37+I37) -> 3000
B39: รวมราคา SWITCH, RECEPTACLE AND OTHER EQUIPMENT | G39: =SUM(G34:G37) -> 10200 | I39: =SUM(I34:I37) -> 5400 | J39: =SUM(J34:J37) -> 15600
A40: 4.5 | B40: งานระบบกันฟ้าผ่าระบบต่อลงดิน
A41: 4.5.1 | B41: Ground Rod | D41: 0 | E41: SET | F41: 1300 | G41: =SUM(D41*F41) -> 0 | I41: =SUM(D41*H41) -> 0 | J41: =SUM(G41+I41) -> 0
A42: 4.5.2 | B42: สายไฟ THW , 750V 70 C ขนาด 70 mm² | D42: 0 | E42: M | F42: 272 | G42: =SUM(D42*F42) -> 0 | I42: =SUM(D42*H42) -> 0 | J42: =SUM(G42+I42) -> 0
A43: 4.5.3 | B43: สายทองแดงเปลือย ขนาด 70 mm² | D43: 0 | E43: M | F43: 267 | G43: =SUM(D43*F43) -> 0 | I43: =SUM(D43*H43) -> 0 | J43: =SUM(G43+I43) -> 0
...
